2024-04-02 19:07:09.420681 - ERROR : send/read tcp data error: Traceback (most recent call last):
  File "d:\Project\Coding\PyAibote\PyAibote\Tool\SendTcpData.py", line 25, in SendData
    response = self.StarLoadWait(data)
  File "d:\Project\Coding\PyAibote\PyAibote\WebBotModel\WebLoadWait.py", line 32, in StarLoadWait
    response = self._Send(data)
  File "d:\Project\Coding\PyAibote\PyAibote\WebBotModel\WebLoadWait.py", line 21, in _Send
    response = self.request.recv(65535)
ConnectionResetError: [WinError 10054] 远程主机强迫关闭了一个现有的连接。

