2024-01-17 05:32:44.658631 - ERROR : send/read tcp data error: Traceback (most recent call last):
  File "d:\Project\Coding\PYAIBOTE\PyAibote\Tool\SendTcpData.py", line 27, in SendData
    response = self.StarLoadWait(data)
               ^^^^^^^^^^^^^^^^^^^^^^^
  File "d:\Project\Coding\PYAIBOTE\PyAibote\AndoridBotModel\AndoridLoadWait.py", line 32, in StarLoadWait
    response = self._Send(data)
               ^^^^^^^^^^^^^^^^
  File "d:\Project\Coding\PYAIBOTE\PyAibote\AndoridBotModel\AndoridLoadWait.py", line 27, in _Send
    raise ConnectionAbortedError(f"{self.client_address[0]}:{self.client_address[1]} Client disconnects")
ConnectionAbortedError: 192.168.31.20:39806 Client disconnects

2024-01-17 08:20:04.933906 - ERROR : send/read tcp data error: Traceback (most recent call last):
  File "d:\Project\Coding\PYAIBOTE\PyAibote\Tool\SendTcpData.py", line 27, in SendData
    response = self.StarLoadWait(data)
               ^^^^^^^^^^^^^^^^^^^^^^^
  File "d:\Project\Coding\PYAIBOTE\PyAibote\AndoridBotModel\AndoridLoadWait.py", line 32, in StarLoadWait
    response = self._Send(data)
               ^^^^^^^^^^^^^^^^
  File "d:\Project\Coding\PYAIBOTE\PyAibote\AndoridBotModel\AndoridLoadWait.py", line 27, in _Send
    raise ConnectionAbortedError(f"{self.client_address[0]}:{self.client_address[1]} Client disconnects")
ConnectionAbortedError: 192.168.31.20:57254 Client disconnects

2024-01-17 16:43:51.768971 - ERROR : send/read tcp data error: Traceback (most recent call last):
  File "d:\Project\Coding\PYAIBOTE\PyAibote\Tool\SendTcpData.py", line 25, in SendData
    response = self.StarLoadWait(data)
               ^^^^^^^^^^^^^^^^^^^^^^^
  File "d:\Project\Coding\PYAIBOTE\PyAibote\AndoridBotModel\AndoridLoadWait.py", line 35, in StarLoadWait
    response = self._Send(data)
               ^^^^^^^^^^^^^^^^
  File "d:\Project\Coding\PYAIBOTE\PyAibote\AndoridBotModel\AndoridLoadWait.py", line 30, in _Send
    raise ConnectionAbortedError(f"{self.client_address[0]}:{self.client_address[1]} Client disconnects")
ConnectionAbortedError: 192.168.31.20:41004 Client disconnects

2024-01-17 21:32:35.806853 - ERROR : send/read tcp data error: Traceback (most recent call last):
  File "d:\Project\Coding\PYAIBOTE\PyAibote\Tool\SendTcpData.py", line 25, in SendData
    response = self.StarLoadWait(data)
               ^^^^^^^^^^^^^^^^^^^^^^^
  File "d:\Project\Coding\PYAIBOTE\PyAibote\AndoridBotModel\AndoridLoadWait.py", line 35, in StarLoadWait
    response = self._Send(data)
               ^^^^^^^^^^^^^^^^
  File "d:\Project\Coding\PYAIBOTE\PyAibote\AndoridBotModel\AndoridLoadWait.py", line 30, in _Send
    raise ConnectionAbortedError(f"{self.client_address[0]}:{self.client_address[1]} Client disconnects")
ConnectionAbortedError: 192.168.31.20:56988 Client disconnects

